Watching for file changes with StatReloader
Error: That port is already in use.
Watching for file changes with StatReloader
Watching for file changes with StatReloader
Error: That port is already in use.
Watching for file changes with StatReloader
[15/Aug/2024 14:57:37] "GET / HTTP/1.1" 200 12068
Not Found: /favicon.ico
[15/Aug/2024 14:57:37] "GET /favicon.ico HTTP/1.1" 404 2209
Watching for file changes with StatReloader
Error: That port is already in use.
/Users/gitce/Documents/django_prueba/prueba1/prueba1/settings.py changed, reloading.
Performing system checks...

System check identified no issues (0 silenced).
August 15, 2024 - 14:57:11
Django version 5.1, using settings 'prueba1.settings'
Starting development server at http://0.0.0.0:8001/
Quit the server with CONTROL-C.

/Users/gitce/Documents/django_prueba/prueba1/prueba1/settings.py changed, reloading.
Performing system checks...

System check identified no issues (0 silenced).
August 15, 2024 - 14:53:39
Django version 5.1, using settings 'prueba1.settings'
Starting development server at http://0.0.0.0:8000/
Quit the server with CONTROL-C.

Watching for file changes with StatReloader
Watching for file changes with StatReloader
/Users/gitce/Documents/django_prueba/prueba1/prueba1/settings.py changed, reloading.
/Users/gitce/Documents/django_prueba/prueba1/prueba1/settings.py changed, reloading.
Performing system checks...

System check identified no issues (0 silenced).
August 15, 2024 - 15:16:37
Django version 5.1, using settings 'prueba1.settings'
Starting development server at http://0.0.0.0:8000/
Quit the server with CONTROL-C.

Performing system checks...

System check identified no issues (0 silenced).
August 15, 2024 - 15:16:37
Django version 5.1, using settings 'prueba1.settings'
Starting development server at http://0.0.0.0:8001/
Quit the server with CONTROL-C.

Watching for file changes with StatReloader
Watching for file changes with StatReloader
Exception in thread django-main-thread:
Exception in thread django-main-thread:
Traceback (most recent call last):
Traceback (most recent call last):
  File "/opt/anaconda3/envs/Django_prueba/lib/python3.12/threading.py", line 1073, in _bootstrap_inner
  File "/opt/anaconda3/envs/Django_prueba/lib/python3.12/threading.py", line 1073, in _bootstrap_inner
    self.run()
  File "/opt/anaconda3/envs/Django_prueba/lib/python3.12/threading.py", line 1010, in run
    self.run()
  File "/opt/anaconda3/envs/Django_prueba/lib/python3.12/threading.py", line 1010, in run
    self._target(*self._args, **self._kwargs)
  File "/opt/anaconda3/envs/Django_prueba/lib/python3.12/site-packages/django/utils/autoreload.py", line 64, in wrapper
    fn(*args, **kwargs)
  File "/opt/anaconda3/envs/Django_prueba/lib/python3.12/site-packages/django/core/management/commands/runserver.py", line 126, in inner_run
    autoreload.raise_last_exception()
    self._target(*self._args, **self._kwargs)
  File "/opt/anaconda3/envs/Django_prueba/lib/python3.12/site-packages/django/utils/autoreload.py", line 87, in raise_last_exception
  File "/opt/anaconda3/envs/Django_prueba/lib/python3.12/site-packages/django/utils/autoreload.py", line 64, in wrapper
    fn(*args, **kwargs)
    raise _exception[1]
  File "/opt/anaconda3/envs/Django_prueba/lib/python3.12/site-packages/django/core/management/commands/runserver.py", line 126, in inner_run
  File "/opt/anaconda3/envs/Django_prueba/lib/python3.12/site-packages/django/core/management/__init__.py", line 394, in execute
    autoreload.raise_last_exception()
  File "/opt/anaconda3/envs/Django_prueba/lib/python3.12/site-packages/django/utils/autoreload.py", line 87, in raise_last_exception
    autoreload.check_errors(django.setup)()
    raise _exception[1]
  File "/opt/anaconda3/envs/Django_prueba/lib/python3.12/site-packages/django/utils/autoreload.py", line 64, in wrapper
  File "/opt/anaconda3/envs/Django_prueba/lib/python3.12/site-packages/django/core/management/__init__.py", line 394, in execute
    fn(*args, **kwargs)
  File "/opt/anaconda3/envs/Django_prueba/lib/python3.12/site-packages/django/__init__.py", line 24, in setup
    autoreload.check_errors(django.setup)()
  File "/opt/anaconda3/envs/Django_prueba/lib/python3.12/site-packages/django/utils/autoreload.py", line 64, in wrapper
    apps.populate(settings.INSTALLED_APPS)
  File "/opt/anaconda3/envs/Django_prueba/lib/python3.12/site-packages/django/apps/registry.py", line 91, in populate
    fn(*args, **kwargs)
  File "/opt/anaconda3/envs/Django_prueba/lib/python3.12/site-packages/django/__init__.py", line 24, in setup
    app_config = AppConfig.create(entry)
                 ^^^^^^^^^^^^^^^^^^^^^^^
  File "/opt/anaconda3/envs/Django_prueba/lib/python3.12/site-packages/django/apps/config.py", line 193, in create
    apps.populate(settings.INSTALLED_APPS)
    import_module(entry)
  File "/opt/anaconda3/envs/Django_prueba/lib/python3.12/site-packages/django/apps/registry.py", line 91, in populate
  File "/opt/anaconda3/envs/Django_prueba/lib/python3.12/importlib/__init__.py", line 90, in import_module
    app_config = AppConfig.create(entry)
    return _bootstrap._gcd_import(name[level:], package, level)
                 ^^^^^^^^^^^^^^^^^^^^^^^
  File "/opt/anaconda3/envs/Django_prueba/lib/python3.12/site-packages/django/apps/config.py", line 193, in create
           ^^^^^^^^^^^^^^^^^^^^^^^^^^^^^^^^^^^^^^^^^^^^^^^^^^^^
  File "<frozen importlib._bootstrap>", line 1384, in _gcd_import
  File "<frozen importlib._bootstrap>", line 1298, in _sanity_check
ValueError: Empty module name
    import_module(entry)
  File "/opt/anaconda3/envs/Django_prueba/lib/python3.12/importlib/__init__.py", line 90, in import_module
    return _bootstrap._gcd_import(name[level:], package, level)
           ^^^^^^^^^^^^^^^^^^^^^^^^^^^^^^^^^^^^^^^^^^^^^^^^^^^^
  File "<frozen importlib._bootstrap>", line 1384, in _gcd_import
  File "<frozen importlib._bootstrap>", line 1298, in _sanity_check
ValueError: Empty module name
/Users/gitce/Documents/django_prueba/prueba1/prueba1/settings.py changed, reloading.
/Users/gitce/Documents/django_prueba/prueba1/prueba1/settings.py changed, reloading.
Watching for file changes with StatReloader
Watching for file changes with StatReloader
/Users/gitce/Documents/django_prueba/prueba1/prueba1/settings.py changed, reloading.
Performing system checks...

System check identified no issues (0 silenced).
August 15, 2024 - 15:17:12
Django version 5.1, using settings 'prueba1.settings'
Starting development server at http://0.0.0.0:8000/
Quit the server with CONTROL-C.

/Users/gitce/Documents/django_prueba/prueba1/prueba1/settings.py changed, reloading.
Performing system checks...

System check identified no issues (0 silenced).
August 15, 2024 - 15:17:12
Django version 5.1, using settings 'prueba1.settings'
Starting development server at http://0.0.0.0:8001/
Quit the server with CONTROL-C.

Watching for file changes with StatReloader
Watching for file changes with StatReloader
/Users/gitce/Documents/django_prueba/prueba1/prueba1/settings.py changed, reloading.
Performing system checks...

System check identified no issues (0 silenced).
August 15, 2024 - 15:17:17
Django version 5.1, using settings 'prueba1.settings'
Starting development server at http://0.0.0.0:8000/
Quit the server with CONTROL-C.

/Users/gitce/Documents/django_prueba/prueba1/prueba1/settings.py changed, reloading.
Performing system checks...

System check identified no issues (0 silenced).
August 15, 2024 - 15:17:17
Django version 5.1, using settings 'prueba1.settings'
Starting development server at http://0.0.0.0:8001/
Quit the server with CONTROL-C.

Watching for file changes with StatReloader
Watching for file changes with StatReloader
Exception in thread django-main-thread:
Exception in thread django-main-thread:
Traceback (most recent call last):
Traceback (most recent call last):
  File "/opt/anaconda3/envs/Django_prueba/lib/python3.12/threading.py", line 1073, in _bootstrap_inner
  File "/opt/anaconda3/envs/Django_prueba/lib/python3.12/threading.py", line 1073, in _bootstrap_inner
    self.run()
    self.run()
  File "/opt/anaconda3/envs/Django_prueba/lib/python3.12/threading.py", line 1010, in run
  File "/opt/anaconda3/envs/Django_prueba/lib/python3.12/threading.py", line 1010, in run
    self._target(*self._args, **self._kwargs)
  File "/opt/anaconda3/envs/Django_prueba/lib/python3.12/site-packages/django/utils/autoreload.py", line 64, in wrapper
    self._target(*self._args, **self._kwargs)
    fn(*args, **kwargs)
  File "/opt/anaconda3/envs/Django_prueba/lib/python3.12/site-packages/django/utils/autoreload.py", line 64, in wrapper
  File "/opt/anaconda3/envs/Django_prueba/lib/python3.12/site-packages/django/core/management/commands/runserver.py", line 126, in inner_run
    fn(*args, **kwargs)
    autoreload.raise_last_exception()
  File "/opt/anaconda3/envs/Django_prueba/lib/python3.12/site-packages/django/core/management/commands/runserver.py", line 126, in inner_run
  File "/opt/anaconda3/envs/Django_prueba/lib/python3.12/site-packages/django/utils/autoreload.py", line 87, in raise_last_exception
    raise _exception[1]
    autoreload.raise_last_exception()
  File "/opt/anaconda3/envs/Django_prueba/lib/python3.12/site-packages/django/utils/autoreload.py", line 87, in raise_last_exception
  File "/opt/anaconda3/envs/Django_prueba/lib/python3.12/site-packages/django/core/management/__init__.py", line 394, in execute
    raise _exception[1]
  File "/opt/anaconda3/envs/Django_prueba/lib/python3.12/site-packages/django/core/management/__init__.py", line 394, in execute
    autoreload.check_errors(django.setup)()
  File "/opt/anaconda3/envs/Django_prueba/lib/python3.12/site-packages/django/utils/autoreload.py", line 64, in wrapper
    fn(*args, **kwargs)
    autoreload.check_errors(django.setup)()
  File "/opt/anaconda3/envs/Django_prueba/lib/python3.12/site-packages/django/__init__.py", line 24, in setup
  File "/opt/anaconda3/envs/Django_prueba/lib/python3.12/site-packages/django/utils/autoreload.py", line 64, in wrapper
    apps.populate(settings.INSTALLED_APPS)
    fn(*args, **kwargs)
  File "/opt/anaconda3/envs/Django_prueba/lib/python3.12/site-packages/django/apps/registry.py", line 91, in populate
  File "/opt/anaconda3/envs/Django_prueba/lib/python3.12/site-packages/django/__init__.py", line 24, in setup
    apps.populate(settings.INSTALLED_APPS)
  File "/opt/anaconda3/envs/Django_prueba/lib/python3.12/site-packages/django/apps/registry.py", line 91, in populate
    app_config = AppConfig.create(entry)
                 ^^^^^^^^^^^^^^^^^^^^^^^
    app_config = AppConfig.create(entry)
  File "/opt/anaconda3/envs/Django_prueba/lib/python3.12/site-packages/django/apps/config.py", line 193, in create
                 ^^^^^^^^^^^^^^^^^^^^^^^
  File "/opt/anaconda3/envs/Django_prueba/lib/python3.12/site-packages/django/apps/config.py", line 193, in create
    import_module(entry)
    import_module(entry)
  File "/opt/anaconda3/envs/Django_prueba/lib/python3.12/importlib/__init__.py", line 90, in import_module
  File "/opt/anaconda3/envs/Django_prueba/lib/python3.12/importlib/__init__.py", line 90, in import_module
    return _bootstrap._gcd_import(name[level:], package, level)
    return _bootstrap._gcd_import(name[level:], package, level)
           ^^^^^^^^^^^^^^^^^^^^^^^^^^^^^^^^^^^^^^^^^^^^^^^^^^^^
  File "<frozen importlib._bootstrap>", line 1387, in _gcd_import
  File "<frozen importlib._bootstrap>", line 1360, in _find_and_load
  File "<frozen importlib._bootstrap>", line 1324, in _find_and_load_unlocked
ModuleNotFoundError: No module named 'ck'
           ^^^^^^^^^^^^^^^^^^^^^^^^^^^^^^^^^^^^^^^^^^^^^^^^^^^^
  File "<frozen importlib._bootstrap>", line 1387, in _gcd_import
  File "<frozen importlib._bootstrap>", line 1360, in _find_and_load
  File "<frozen importlib._bootstrap>", line 1324, in _find_and_load_unlocked
ModuleNotFoundError: No module named 'ck'
/Users/gitce/Documents/django_prueba/prueba1/prueba1/settings.py changed, reloading.
/Users/gitce/Documents/django_prueba/prueba1/prueba1/settings.py changed, reloading.
Watching for file changes with StatReloader
Watching for file changes with StatReloader
System check identified some issues:

WARNINGS:
?: (ckeditor.W001) django-ckeditor bundles CKEditor 4.22.1 which isn't supported anmyore and which does have unfixed security issues, see for example https://ckeditor.com/cke4/release/CKEditor-4.24.0-LTS . You should consider strongly switching to a different editor (maybe CKEditor 5 respectively django-ckeditor-5 after checking whether the CKEditor 5 license terms work for you) or switch to the non-free CKEditor 4 LTS package. See https://ckeditor.com/ckeditor-4-support/ for more on this. (Note! This notice has been added by the django-ckeditor developers and we are not affiliated with CKSource and were not involved in the licensing change, so please refrain from complaining to us. Thanks.)

System check identified 1 issue (0 silenced).
System check identified some issues:

WARNINGS:
?: (ckeditor.W001) django-ckeditor bundles CKEditor 4.22.1 which isn't supported anmyore and which does have unfixed security issues, see for example https://ckeditor.com/cke4/release/CKEditor-4.24.0-LTS . You should consider strongly switching to a different editor (maybe CKEditor 5 respectively django-ckeditor-5 after checking whether the CKEditor 5 license terms work for you) or switch to the non-free CKEditor 4 LTS package. See https://ckeditor.com/ckeditor-4-support/ for more on this. (Note! This notice has been added by the django-ckeditor developers and we are not affiliated with CKSource and were not involved in the licensing change, so please refrain from complaining to us. Thanks.)

System check identified 1 issue (0 silenced).
/Users/gitce/Documents/django_prueba/prueba1/prueba1/settings.py changed, reloading.
/Users/gitce/Documents/django_prueba/prueba1/prueba1/settings.py changed, reloading.
Performing system checks...

August 15, 2024 - 15:18:05
Django version 5.1, using settings 'prueba1.settings'
Starting development server at http://0.0.0.0:8001/
Quit the server with CONTROL-C.

Performing system checks...

August 15, 2024 - 15:18:05
Django version 5.1, using settings 'prueba1.settings'
Starting development server at http://0.0.0.0:8000/
Quit the server with CONTROL-C.

Watching for file changes with StatReloader
Watching for file changes with StatReloader
System check identified some issues:

WARNINGS:
?: (ckeditor.W001) django-ckeditor bundles CKEditor 4.22.1 which isn't supported anmyore and which does have unfixed security issues, see for example https://ckeditor.com/cke4/release/CKEditor-4.24.0-LTS . You should consider strongly switching to a different editor (maybe CKEditor 5 respectively django-ckeditor-5 after checking whether the CKEditor 5 license terms work for you) or switch to the non-free CKEditor 4 LTS package. See https://ckeditor.com/ckeditor-4-support/ for more on this. (Note! This notice has been added by the django-ckeditor developers and we are not affiliated with CKSource and were not involved in the licensing change, so please refrain from complaining to us. Thanks.)

System check identified 1 issue (0 silenced).
System check identified some issues:

WARNINGS:
?: (ckeditor.W001) django-ckeditor bundles CKEditor 4.22.1 which isn't supported anmyore and which does have unfixed security issues, see for example https://ckeditor.com/cke4/release/CKEditor-4.24.0-LTS . You should consider strongly switching to a different editor (maybe CKEditor 5 respectively django-ckeditor-5 after checking whether the CKEditor 5 license terms work for you) or switch to the non-free CKEditor 4 LTS package. See https://ckeditor.com/ckeditor-4-support/ for more on this. (Note! This notice has been added by the django-ckeditor developers and we are not affiliated with CKSource and were not involved in the licensing change, so please refrain from complaining to us. Thanks.)

System check identified 1 issue (0 silenced).
/Users/gitce/Documents/django_prueba/prueba1/prueba1/settings.py changed, reloading.
/Users/gitce/Documents/django_prueba/prueba1/prueba1/settings.py changed, reloading.
Performing system checks...

August 15, 2024 - 15:18:46
Django version 5.1, using settings 'prueba1.settings'
Starting development server at http://0.0.0.0:8000/
Quit the server with CONTROL-C.

Performing system checks...

August 15, 2024 - 15:18:46
Django version 5.1, using settings 'prueba1.settings'
Starting development server at http://0.0.0.0:8001/
Quit the server with CONTROL-C.

Traceback (most recent call last):
  File "/Users/gitce/Documents/django_prueba/prueba1/manage.py", line 22, in <module>
Traceback (most recent call last):
  File "/Users/gitce/Documents/django_prueba/prueba1/manage.py", line 22, in <module>
    main()
  File "/Users/gitce/Documents/django_prueba/prueba1/manage.py", line 18, in main
    execute_from_command_line(sys.argv)
  File "/opt/anaconda3/envs/Django_prueba/lib/python3.12/site-packages/django/core/management/__init__.py", line 442, in execute_from_command_line
    main()
  File "/Users/gitce/Documents/django_prueba/prueba1/manage.py", line 18, in main
    execute_from_command_line(sys.argv)
  File "/opt/anaconda3/envs/Django_prueba/lib/python3.12/site-packages/django/core/management/__init__.py", line 442, in execute_from_command_line
    utility.execute()
    utility.execute()
  File "/opt/anaconda3/envs/Django_prueba/lib/python3.12/site-packages/django/core/management/__init__.py", line 382, in execute
  File "/opt/anaconda3/envs/Django_prueba/lib/python3.12/site-packages/django/core/management/__init__.py", line 382, in execute
    settings.INSTALLED_APPS
    settings.INSTALLED_APPS
  File "/opt/anaconda3/envs/Django_prueba/lib/python3.12/site-packages/django/conf/__init__.py", line 81, in __getattr__
  File "/opt/anaconda3/envs/Django_prueba/lib/python3.12/site-packages/django/conf/__init__.py", line 81, in __getattr__
    self._setup(name)
  File "/opt/anaconda3/envs/Django_prueba/lib/python3.12/site-packages/django/conf/__init__.py", line 68, in _setup
    self._setup(name)
  File "/opt/anaconda3/envs/Django_prueba/lib/python3.12/site-packages/django/conf/__init__.py", line 68, in _setup
    self._wrapped = Settings(settings_module)
    self._wrapped = Settings(settings_module)
                    ^^^^^^^^^^^^^^^^^^^^^^^^^
                    ^^^^^^^^^^^^^^^^^^^^^^^^^
  File "/opt/anaconda3/envs/Django_prueba/lib/python3.12/site-packages/django/conf/__init__.py", line 166, in __init__
  File "/opt/anaconda3/envs/Django_prueba/lib/python3.12/site-packages/django/conf/__init__.py", line 166, in __init__
    mod = importlib.import_module(self.SETTINGS_MODULE)
          ^^^^^^^^^^^^^^^^^^^^^^^^^^^^^^^^^^^^^^^^^^^^^
  File "/opt/anaconda3/envs/Django_prueba/lib/python3.12/importlib/__init__.py", line 90, in import_module
    mod = importlib.import_module(self.SETTINGS_MODULE)
          ^^^^^^^^^^^^^^^^^^^^^^^^^^^^^^^^^^^^^^^^^^^^^
  File "/opt/anaconda3/envs/Django_prueba/lib/python3.12/importlib/__init__.py", line 90, in import_module
    return _bootstrap._gcd_import(name[level:], package, level)
    return _bootstrap._gcd_import(name[level:], package, level)
           ^^^^^^^^^^^^^^^^^^^^^^^^^^^^^^^^^^^^^^^^^^^^^^^^^^^^
  File "<frozen importlib._bootstrap>", line 1387, in _gcd_import
  File "<frozen importlib._bootstrap>", line 1360, in _find_and_load
  File "<frozen importlib._bootstrap>", line 1331, in _find_and_load_unlocked
           ^^^^^^^^^^^^^^^^^^^^^^^^^^^^^^^^^^^^^^^^^^^^^^^^^^^^
  File "<frozen importlib._bootstrap>", line 935, in _load_unlocked
  File "<frozen importlib._bootstrap>", line 1387, in _gcd_import
  File "<frozen importlib._bootstrap_external>", line 995, in exec_module
  File "<frozen importlib._bootstrap>", line 1360, in _find_and_load
  File "<frozen importlib._bootstrap>", line 488, in _call_with_frames_removed
  File "<frozen importlib._bootstrap>", line 1331, in _find_and_load_unlocked
  File "/Users/gitce/Documents/django_prueba/prueba1/prueba1/settings.py", line 121, in <module>
  File "<frozen importlib._bootstrap>", line 935, in _load_unlocked
  File "<frozen importlib._bootstrap_external>", line 995, in exec_module
  File "<frozen importlib._bootstrap>", line 488, in _call_with_frames_removed
  File "/Users/gitce/Documents/django_prueba/prueba1/prueba1/settings.py", line 121, in <module>
    S
NameError: name 'S' is not defined
    S
NameError: name 'S' is not defined
